<?xml version="1.0" encoding='utf-8'?>
<!-- =================================================================================== -->
<!-- |    This document was autogenerated by xacro from ur10e_robot.urdf.xacro         | -->
<!-- |    EDITING THIS FILE BY HAND IS NOT RECOMMENDED                                 | -->
<!-- =================================================================================== -->
<robot xmlns:xacro="http://www.ros.org/wiki/xacro">
  <xacro:macro name="ur5e" params="name tf_prefix connected_to rpy xyz">
    <!-- <xacro:property name="tf_prefix" value="${tf_prefix}" /> -->
    <!-- <xacro:property name="name" value="${name}" /> -->

    <joint name="${tf_prefix}world_joint" type="fixed">
      <parent link="${connected_to}" />
      <child link = "${tf_prefix}base" />
      <origin xyz="0.0 0.0 0.0" rpy="0.0 0.0 0.0" />
    </joint>
    <!-- ROS base_link to UR 'Base' Coordinates transform -->
    <link name="${tf_prefix}base">
      <!-- <visual>
      <origin rpy="0 0 0" xyz="0 0 0.5"/>
      <geometry>
        <box size="1 2 1"/>
      </geometry>
      <material name="White">
        <color rgba="1.0 1.0 1.0 1.0"/>
      </material>
    </visual>
    <collision>
      <origin rpy="0 0 0" xyz="0 0 0.5"/>
      <geometry>
        <box size="1 2 1"/>
      </geometry>
    </collision> -->
    </link>
    <joint name="${tf_prefix}base_link-${tf_prefix}base_fixed_joint" type="fixed">
      <!-- 
          NOTE: this rotation is only needed as long as base_link itself is
                 not corrected wrt the real robot (ie: rotated over 180
                 degrees)
      -->
      <origin xyz="${xyz}" rpy="${rpy}" />
      <parent link="${tf_prefix}base" />
      <child link="${tf_prefix}base_link" />
    </joint>


    <link name="${tf_prefix}base_link">
      <visual>
        <geometry>
          <mesh filename="$(find mujoco_ros2_ur)/ur_description/meshes/ur5e/visual/base.dae" />
        </geometry>
        <material name="LightGrey">
          <color rgba="0.7 0.7 0.7 1.0" />
        </material>
      </visual>
      <collision>
        <geometry>
          <mesh
            filename="$(find mujoco_ros2_ur)/ur_description/meshes/ur5e/collision/meshes/base_vis.stl" />
        </geometry>
      </collision>
      <inertial>
        <mass value="4.0" />
        <origin rpy="0 0 0" xyz="0.0 0.0 0.0" />
        <inertia ixx="0.00443333156" ixy="0.0" ixz="0.0" iyy="0.00443333156" iyz="0.0" izz="0.0072" />
      </inertial>
    </link>
    <joint name="${tf_prefix}shoulder_pan_joint" type="revolute">
      <parent link="${tf_prefix}base_link" />
      <child link="${tf_prefix}shoulder_link" />
      <origin rpy="0.0 0.0 0.0" xyz="0.0 0.0 0.163" />
      <axis xyz="0 0 1" />
      <limit effort="150.0" lower="-6.283185307179586" upper="6.283185307179586" velocity="3.14" />
      <dynamics damping="0.0" friction="0.0" />
    </joint>
    <link name="${tf_prefix}shoulder_link">
      <visual>
        <geometry>
          <mesh filename="$(find mujoco_ros2_ur)/ur_description/meshes/ur5e/visual/shoulder.dae" />
        </geometry>
        <material name="LightGrey">
          <color rgba="0.7 0.7 0.7 1.0" />
        </material>
      </visual>
      <collision>
        <geometry>
          <mesh
            filename="$(find mujoco_ros2_ur)/ur_description/meshes/ur5e/collision/meshes/shoulder_vis.stl" />
        </geometry>
      </collision>
      <inertial>
        <mass value="3.7" />
        <origin rpy="0 0 0" xyz="0.0 0.0 0.0" />
        <inertia ixx="0.010267495893" ixy="0.0" ixz="0.0" iyy="0.010267495893" iyz="0.0"
          izz="0.00666" />
      </inertial>
    </link>
    <joint name="${tf_prefix}shoulder_lift_joint" type="revolute">
      <parent link="${tf_prefix}shoulder_link" />
      <child link="${tf_prefix}upper_arm_link" />
      <origin rpy="0.0 1.5707963267948966 0.0" xyz="0.0 0.138 0.0" />
      <axis xyz="0 1 0" />
      <limit effort="150.0" lower="-6.283185307179586" upper="6.283185307179586" velocity="3.14" />
      <dynamics damping="0.0" friction="0.0" />
    </joint>

    <link name="${tf_prefix}upper_arm_link">
      <visual>
        <geometry>
          <mesh filename="$(find mujoco_ros2_ur)/ur_description/meshes/ur5e/visual/upperarm.dae" />
        </geometry>
        <material name="LightGrey">
          <color rgba="0.7 0.7 0.7 1.0" />
        </material>
      </visual>
      <collision>
        <geometry>
          <mesh
            filename="$(find mujoco_ros2_ur)/ur_description/meshes/ur5e/collision/meshes/upperarm_vis.stl" />
        </geometry>
      </collision>
      <inertial>
        <mass value="8.393" />
        <origin rpy="0 0 0" xyz="0.0 0.0 0.28" />
        <inertia ixx="0.22689067591036005" ixy="0.0" ixz="0.0" iyy="0.22689067591036005" iyz="0.0"
          izz="0.0151074" />
      </inertial>
    </link>
    <joint name="${tf_prefix}elbow_joint" type="revolute">
      <parent link="${tf_prefix}upper_arm_link" />
      <child link="${tf_prefix}forearm_link" />
      <origin rpy="0.0 0.0 0.0" xyz="0.0 -0.131 0.425" />
      <axis xyz="0 1 0" />
      <limit effort="150.0" lower="-3.141592653589793" upper="3.141592653589793" velocity="3.14" />
      <dynamics damping="0.0" friction="0.0" />
    </joint>
    <link name="${tf_prefix}forearm_link">
      <visual>
        <geometry>
          <mesh filename="$(find mujoco_ros2_ur)/ur_description/meshes/ur5e/visual/forearm.dae" />
        </geometry>
        <material name="LightGrey">
          <color rgba="0.7 0.7 0.7 1.0" />
        </material>
      </visual>
      <collision>
        <geometry>
          <mesh
            filename="$(find mujoco_ros2_ur)/ur_description/meshes/ur5e/collision/meshes/forearm_vis.stl" />
        </geometry>
      </collision>
      <inertial>
        <mass value="2.275" />
        <origin rpy="0 0 0" xyz="0.0 0.0 0.25" />
        <inertia ixx="0.04944331355599999" ixy="0.0" ixz="0.0" iyy="0.04944331355599999" iyz="0.0"
          izz="0.004095" />
      </inertial>
    </link>

    <joint name="${tf_prefix}wrist_1_joint" type="revolute">
      <parent link="${tf_prefix}forearm_link" />
      <child link="${tf_prefix}wrist_1_link" />
      <origin rpy="0.0 1.5707963267948966 0.0" xyz="0.0 0.0 0.392" />
      <axis xyz="0 1 0" />
      <limit effort="28.0" lower="-6.283185307179586" upper="6.283185307179586" velocity="6.28" />
      <dynamics damping="0.0" friction="0.0" />
    </joint>

    <link name="${tf_prefix}wrist_1_link">
      <visual>
        <geometry>
          <mesh filename="$(find mujoco_ros2_ur)/ur_description/meshes/ur5e/visual/wrist1.dae" />
        </geometry>
        <material name="LightGrey">
          <color rgba="0.7 0.7 0.7 1.0" />
        </material>
      </visual>
      <collision>
        <geometry>
          <mesh
            filename="$(find mujoco_ros2_ur)/ur_description/meshes/ur5e/collision/meshes/wrist1_vis.stl" />
        </geometry>
      </collision>
      <inertial>
        <mass value="1.219" />
        <origin rpy="0 0 0" xyz="0.0 0 0.0" />
        <inertia ixx="0.11117275553087999" ixy="0.0" ixz="0.0" iyy="0.11117275553087999" iyz="0.0"
          izz="0.0021942" />
      </inertial>
    </link>

    <joint name="${tf_prefix}wrist_2_joint" type="revolute">
      <parent link="${tf_prefix}wrist_1_link" />
      <child link="${tf_prefix}wrist_2_link" />
      <origin rpy="0.0 0.0 0.0" xyz="0.0 0.127 0.0" />
      <axis xyz="0 0 1" />
      <limit effort="28.0" lower="-6.283185307179586" upper="6.283185307179586" velocity="6.28" />
      <dynamics damping="0.0" friction="0.0" />
    </joint>
    <link name="${tf_prefix}wrist_2_link">
      <visual>
        <geometry>
          <mesh filename="$(find mujoco_ros2_ur)/ur_description/meshes/ur5e/visual/wrist2.dae" />
        </geometry>
        <material name="LightGrey">
          <color rgba="0.7 0.7 0.7 1.0" />
        </material>
      </visual>
      <collision>
        <geometry>
          <mesh
            filename="$(find mujoco_ros2_ur)/ur_description/meshes/ur5e/collision/meshes/wrist2_vis.stl" />
        </geometry>
      </collision>
      <inertial>
        <mass value="1.219" />
        <origin rpy="0 0 0" xyz="0.0 0.0 0" />
        <inertia ixx="0.11117275553087999" ixy="0.0" ixz="0.0" iyy="0.11117275553087999" iyz="0.0"
          izz="0.21942" />
      </inertial>
    </link>

    <joint name="${tf_prefix}wrist_3_joint" type="revolute">
      <parent link="${tf_prefix}wrist_2_link" />
      <child link="${tf_prefix}wrist_3_link" />
      <origin rpy="0.0 0.0 0.0" xyz="0.0 0.0 0.100" />
      <axis xyz="0 1 0" />
      <limit effort="28.0" lower="-6.283185307179586" upper="6.283185307179586" velocity="6.28" />
      <dynamics damping="0.0" friction="0.0" />
    </joint>
    <link name="${tf_prefix}wrist_3_link">
      <visual>
        <geometry>
          <mesh filename="$(find mujoco_ros2_ur)/ur_description/meshes/ur5e/visual/wrist3.dae" />
        </geometry>
        <material name="LightGrey">
          <color rgba="0.7 0.7 0.7 1.0" />
        </material>
      </visual>
      <collision>
        <geometry>
          <mesh
            filename="$(find mujoco_ros2_ur)/ur_description/meshes/ur5e/collision/meshes/wrist3_vis.stl" />
        </geometry>
      </collision>
      <inertial>
        <mass value="0.1879" />
        <origin rpy="0 0 0" xyz="0.0 0 0.0" />
        <inertia ixx="0.017136473145408" ixy="0.0" ixz="0.0" iyy="0.017136473145408" iyz="0.0"
          izz="0.033822" />
      </inertial>
    </link>
    <joint name="${tf_prefix}ee_fixed_joint" type="fixed">
      <parent link="${tf_prefix}wrist_3_link" />
      <child link="${tf_prefix}ee_link" />
      <origin rpy="0.0 0.0 1.5707963267948966" xyz="0.0 0.100 0.0" />
    </joint>
    <link name="${tf_prefix}ee_link">
      <collision>
        <geometry>
          <box size="0.01 0.01 0.01" />
        </geometry>
        <origin rpy="0 0 0" xyz="-0.01 0 0" />
      </collision>
    </link>


    <!-- Frame coincident with all-zeros TCP on UR controller -->
    <link name="${tf_prefix}tool0" />
    <joint name="${tf_prefix}wrist_3_link-${tf_prefix}tool0_fixed_joint" type="fixed">
      <origin xyz="0 0.0834 0" rpy="-1.5707963267948966 0 0" />
      <parent link="${tf_prefix}wrist_3_link" />
      <child link="${tf_prefix}tool0" />
    </joint>


    <!-- Force/Torque sensor -->
    <!--<xacro:include
    filename="$(find ur_description)/urdf/ur5e/ur5e/ForceTorqueSensor.xacro" /> -->


    <!-- <transmission name="shoulder_pan_trans">
    <type>transmission_interface/SimpleTransmission</type>
    <joint name="shoulder_pan_joint">
      <hardwareInterface>hardware_interface/VelocityJointInterface</hardwareInterface>
    </joint>
    <actuator name="shoulder_pan_motor">
      <mechanicalReduction>1</mechanicalReduction>
    </actuator>
  </transmission>

  <transmission name="shoulder_lift_trans">
    <type>transmission_interface/SimpleTransmission</type>
    <joint name="shoulder_lift_joint">
      <hardwareInterface>hardware_interface/VelocityJointInterface</hardwareInterface>
    </joint>
    <actuator name="shoulder_lift_motor">
      <mechanicalReduction>1</mechanicalReduction>
    </actuator>
  </transmission>

  <transmission name="elbow_trans">
    <type>transmission_interface/SimpleTransmission</type>
    <joint name="elbow_joint">
      <hardwareInterface>hardware_interface/VelocityJointInterface</hardwareInterface>
    </joint>
    <actuator name="elbow_motor">
      <mechanicalReduction>1</mechanicalReduction>
    </actuator>
  </transmission>

  <transmission name="wrist_1_trans">
    <type>transmission_interface/SimpleTransmission</type>
    <joint name="wrist_1_joint">
      <hardwareInterface>hardware_interface/VelocityJointInterface</hardwareInterface>
    </joint>
    <actuator name="wrist_1_motor">
      <mechanicalReduction>1</mechanicalReduction>
    </actuator>
  </transmission>

  <transmission name="wrist_2_trans">
    <type>transmission_interface/SimpleTransmission</type>
    <joint name="wrist_2_joint">
      <hardwareInterface>hardware_interface/VelocityJointInterface</hardwareInterface>
    </joint>
    <actuator name="wrist_2_motor">
      <mechanicalReduction>1</mechanicalReduction>
    </actuator>
  </transmission>

  <transmission name="wrist_3_trans">
    <type>transmission_interface/SimpleTransmission</type>
    <joint name="wrist_3_joint">
      <hardwareInterface>hardware_interface/VelocityJointInterface</hardwareInterface>
    </joint>
    <actuator name="wrist_3_motor">
      <mechanicalReduction>1</mechanicalReduction>
    </actuator>
  </transmission> -->

    <joint name="${tf_prefix}robotiq_85_base_joint" type="fixed">
      <parent link="${tf_prefix}ee_link" />
      <child link="${tf_prefix}robotiq_85_base_link" />
      <origin rpy="1.5707963267948966 0 0" xyz="-0.011 0 0.0" />
    </joint>

    <link name="${tf_prefix}robotiq_85_base_link">
      <visual>
        <geometry>
          <mesh
            filename="$(find mujoco_ros2_ur)/ur_description/urdf/ur5e/robotiq/robotiq_description/meshes/visual/robotiq_85_base_link.dae" />
        </geometry>
      </visual>
      <collision>
        <geometry>
          <mesh
            filename="$(find mujoco_ros2_ur)/ur_description/urdf/ur5e/robotiq/robotiq_description/meshes/collision/robotiq_85_base_link.stl" />
        </geometry>
      </collision>
      <inertial>
        <mass value="0.636951" />
        <origin xyz="0.0 0.0 0.0" />
        <inertia ixx="0.000380" ixy="0.000000" ixz="0.000000"
          iyx="0.000000" iyy="0.001110" iyz="0.000000"
          izx="0.000000" izy="0.000000" izz="0.001171" />
      </inertial>
    </link>

    <joint name="${tf_prefix}robotiq_85_left_knuckle_joint" type="revolute">
      <parent link="${tf_prefix}robotiq_85_base_link" />
      <child link="${tf_prefix}robotiq_85_left_knuckle_link" />
      <axis xyz="0 0 1" />
      <origin rpy="3.141592653589793 0.0 0.0" xyz="0.05490451627 0.03060114443 0.0" />
      <limit lower="0.0" upper="0.840" velocity="2.0" effort="1000" />
    </joint>

    <joint name="${tf_prefix}robotiq_85_right_knuckle_joint" type="continuous">
      <parent link="${tf_prefix}robotiq_85_base_link" />
      <child link="${tf_prefix}robotiq_85_right_knuckle_link" />
      <axis xyz="0 0 1" />
      <origin rpy="0.0 0.0 0.0" xyz="0.05490451627 -0.03060114443 0.0" />
      <limit lower="-3.14" upper="3.14" velocity="100.0" effort="1000" />
      <mimic joint="${tf_prefix}robotiq_85_left_knuckle_joint" />
    </joint>

    <link name="${tf_prefix}robotiq_85_left_knuckle_link">
      <visual>
        <geometry>
          <mesh
            filename="$(find mujoco_ros2_ur)/ur_description/urdf/ur5e/robotiq/robotiq_description/meshes/visual/robotiq_85_knuckle_link.dae" />
        </geometry>
      </visual>
      <collision>
        <geometry>
          <mesh
            filename="$(find mujoco_ros2_ur)/ur_description/urdf/ur5e/robotiq/robotiq_description/meshes/collision/robotiq_85_knuckle_link.stl" />
        </geometry>
      </collision>
      <inertial>
        <mass value="0.018491" />
        <origin xyz="0.0 0.0 0.0" />
        <inertia ixx="0.000009" ixy="-0.000001" ixz="0.000000"
          iyx="-0.000001" iyy="0.000001" iyz="0.000000"
          izx="0.000000" izy="0.000000" izz="0.000010" />
      </inertial>
    </link>

    <link name="${tf_prefix}robotiq_85_right_knuckle_link">
      <visual>
        <geometry>
          <mesh
            filename="$(find mujoco_ros2_ur)/ur_description/urdf/ur5e/robotiq/robotiq_description/meshes/visual/robotiq_85_knuckle_link.dae" />
        </geometry>
      </visual>
      <collision>
        <geometry>
          <mesh
            filename="$(find mujoco_ros2_ur)/ur_description/urdf/ur5e/robotiq/robotiq_description/meshes/collision/robotiq_85_knuckle_link.stl" />
        </geometry>
      </collision>
      <inertial>
        <mass value="0.018491" />
        <origin xyz="0.0 0.0 0.0" />
        <inertia ixx="0.000009" ixy="-0.000001" ixz="0.000000"
          iyx="-0.000001" iyy="0.000001" iyz="0.000000"
          izx="0.000000" izy="0.000000" izz="0.000010" />
      </inertial>
    </link>

    <joint name="${tf_prefix}robotiq_85_left_finger_joint" type="continuous">
      <parent link="${tf_prefix}robotiq_85_left_knuckle_link" />
      <child link="${tf_prefix}robotiq_85_left_finger_link" />
      <origin xyz="-0.0041 -0.0315 0.0" rpy="0 0 0" />
    </joint>

    <joint name="${tf_prefix}robotiq_85_right_finger_joint" type="continuous">
      <parent link="${tf_prefix}robotiq_85_right_knuckle_link" />
      <child link="${tf_prefix}robotiq_85_right_finger_link" />
      <origin xyz="-0.0041 -0.0315 0.0" rpy="0 0 0" />
    </joint>

    <link name="${tf_prefix}robotiq_85_left_finger_link">
      <visual>
        <geometry>
          <mesh
            filename="$(find mujoco_ros2_ur)/ur_description/urdf/ur5e/robotiq/robotiq_description/meshes/visual/robotiq_85_finger_link.dae" />
        </geometry>
      </visual>
      <collision>
        <geometry>
          <mesh
            filename="$(find mujoco_ros2_ur)/ur_description/urdf/ur5e/robotiq/robotiq_description/meshes/collision/robotiq_85_finger_link.stl" />
        </geometry>
      </collision>
      <inertial>
        <mass value="0.027309" />
        <origin xyz="0.0 0.0 0.0" />
        <inertia ixx="0.000003" ixy="-0.000002" ixz="0.000000"
          iyx="-0.000002" iyy="0.000021" iyz="0.000000"
          izx="0.000000" izy="0.000000" izz="0.000020" />
      </inertial>
    </link>

    <link name="${tf_prefix}robotiq_85_right_finger_link">
      <visual>
        <geometry>
          <mesh
            filename="$(find mujoco_ros2_ur)/ur_description/urdf/ur5e/robotiq/robotiq_description/meshes/visual/robotiq_85_finger_link.dae" />
        </geometry>
      </visual>
      <collision>
        <geometry>
          <mesh
            filename="$(find mujoco_ros2_ur)/ur_description/urdf/ur5e/robotiq/robotiq_description/meshes/collision/robotiq_85_finger_link.stl" />
        </geometry>
      </collision>
      <inertial>
        <mass value="0.027309" />
        <origin xyz="0.0 0.0 0.0" />
        <inertia ixx="0.000003" ixy="-0.000002" ixz="0.000000"
          iyx="-0.000002" iyy="0.000021" iyz="0.000000"
          izx="0.000000" izy="0.000000" izz="0.000020" />
      </inertial>
    </link>

    <joint name="${tf_prefix}robotiq_85_left_inner_knuckle_joint" type="continuous">
      <parent link="${tf_prefix}robotiq_85_base_link" />
      <child link="${tf_prefix}robotiq_85_left_inner_knuckle_link" />
      <axis xyz="0 0 1" />
      <origin xyz="0.0609 0.0132 0" rpy="3.141592653589793 0.0 0.0" />
      <limit lower="-3.14" upper="3.14" velocity="100.0" effort="0.1" />
      <mimic joint="${tf_prefix}robotiq_85_left_knuckle_joint" offset="0" />
    </joint>

    <joint name="${tf_prefix}robotiq_85_right_inner_knuckle_joint" type="continuous">
      <parent link="${tf_prefix}robotiq_85_base_link" />
      <child link="${tf_prefix}robotiq_85_right_inner_knuckle_link" />
      <axis xyz="0 0 1" />
      <origin xyz="0.0609 -0.0132 0" rpy="0 0 0" />
      <limit lower="-3.14" upper="3.14" velocity="100.0" effort="0.1" />
      <mimic joint="${tf_prefix}robotiq_85_left_knuckle_joint" offset="0" />
    </joint>

    <link name="${tf_prefix}robotiq_85_left_inner_knuckle_link">
      <visual>
        <geometry>
          <mesh
            filename="$(find mujoco_ros2_ur)/ur_description/urdf/ur5e/robotiq/robotiq_description/meshes/visual/robotiq_85_inner_knuckle_link.dae" />
        </geometry>
      </visual>
      <collision>
        <geometry>
          <mesh
            filename="$(find mujoco_ros2_ur)/ur_description/urdf/ur5e/robotiq/robotiq_description/meshes/collision/robotiq_85_inner_knuckle_link.stl" />
        </geometry>
      </collision>
      <inertial>
        <mass value="0.029951" />
        <origin xyz="0.0 0.0 0.0" />
        <inertia ixx="0.000039" ixy="0.000000" ixz="0.000000"
          iyx="0.000000" iyy="0.000005" iyz="0.000000"
          izx="0.000000" izy="0.000000" izz="0.000035" />
      </inertial>
    </link>

    <link name="${tf_prefix}robotiq_85_right_inner_knuckle_link">
      <visual>
        <geometry>
          <mesh
            filename="$(find mujoco_ros2_ur)/ur_description/urdf/ur5e/robotiq/robotiq_description/meshes/visual/robotiq_85_inner_knuckle_link.dae" />
        </geometry>
      </visual>
      <collision>
        <geometry>
          <mesh
            filename="$(find mujoco_ros2_ur)/ur_description/urdf/ur5e/robotiq/robotiq_description/meshes/collision/robotiq_85_inner_knuckle_link.stl" />
        </geometry>
      </collision>
      <inertial>
        <mass value="0.029951" />
        <origin xyz="0.0 0.0 0.0" />
        <inertia ixx="0.000039" ixy="0.000000" ixz="0.000000"
          iyx="0.000000" iyy="0.000005" iyz="0.000000"
          izx="0.000000" izy="0.000000" izz="0.000035" />
      </inertial>
    </link>

    <joint name="${tf_prefix}robotiq_85_left_finger_tip_joint" type="continuous">
      <parent link="${tf_prefix}robotiq_85_left_inner_knuckle_link" />
      <child link="${tf_prefix}robotiq_85_left_finger_tip_link" />
      <axis xyz="0 0 1" />
      <origin xyz="0.04303 -0.03759940821 0.0" rpy="0.0 0.0 0.0" />
      <!-- 0.04303959807 -->
      <limit lower="-3.14" upper="3.14" velocity="100.0" effort="0.1" />
      <mimic joint="${tf_prefix}robotiq_85_left_knuckle_joint" multiplier="-1" />
    </joint>

    <joint name="${tf_prefix}robotiq_85_right_finger_tip_joint" type="continuous">
      <parent link="${tf_prefix}robotiq_85_right_inner_knuckle_link" />
      <child link="${tf_prefix}robotiq_85_right_finger_tip_link" />
      <axis xyz="0 0 1" />
      <origin rpy="0.0 0.0 0.0" xyz="0.04303 -0.03759940821  0.0" />
      <!-- 0.04303959807 -->
      <limit lower="-3.14" upper="3.14" velocity="100.0" effort="0.1" />
      <mimic joint="${tf_prefix}robotiq_85_left_knuckle_joint" multiplier="-1" />
    </joint>


    <link name="${tf_prefix}robotiq_85_left_finger_tip_link">
      <visual>
        <geometry>
          <mesh
            filename="$(find mujoco_ros2_ur)/ur_description/urdf/ur5e/ur5e/robotiq/robotiq_description/meshes/visual/robotiq_85_finger_tip_link.dae" />
        </geometry>
      </visual>
      <collision>
        <geometry>
          <mesh
            filename="$(find mujoco_ros2_ur)/ur_description/urdf/ur5e/robotiq/robotiq_description/meshes/collision/robotiq_85_finger_tip_link.stl" />
        </geometry>
      </collision>
      <inertial>
        <mass value="0.019555" />
        <origin xyz="0.0 0.0 0.0" />
        <inertia ixx="0.000002" ixy="0.000000" ixz="0.000000"
          iyx="0.000000" iyy="0.000005" iyz="0.000000"
          izx="0.000000" izy="0.000000" izz="0.000006" />
      </inertial>
    </link>

    <link name="${tf_prefix}robotiq_85_right_finger_tip_link">
      <visual>
        <geometry>
          <mesh
            filename="$(find mujoco_ros2_ur)/ur_description/urdf/ur5e/robotiq/robotiq_description/meshes/visual/robotiq_85_finger_tip_link.dae" />
        </geometry>
      </visual>
      <collision>
        <geometry>
          <mesh
            filename="$(find mujoco_ros2_ur)/ur_description/urdf/ur5e/robotiq/robotiq_description/meshes/collision/robotiq_85_finger_tip_link.stl" />
        </geometry>
      </collision>
      <inertial>
        <mass value="0.019555" />
        <origin xyz="0.0 0.0 0.0" />
        <inertia ixx="0.000002" ixy="0.000000" ixz="0.000000"
          iyx="0.000000" iyy="0.000005" iyz="0.000000"
          izx="0.000000" izy="0.000000" izz="0.000006" />
      </inertial>
    </link>


    <!-- <transmission name="robotiq_85_left_knuckle_trans">
    <type>transmission_interface/SimpleTransmission</type>
    <joint name="robotiq_85_left_knuckle_joint">
      <hardwareInterface>hardware_interface/PositionJointInterface</hardwareInterface>
    </joint>
    <actuator name="robotiq_85_left_knuckle_motor">
      <mechanicalReduction>1</mechanicalReduction>
      <hardwareInterface>hardware_interface/PositionJointInterface</hardwareInterface>
    </actuator>
  </transmission> -->

    <!-- <link name="peg">
    <collision>
      <geometry>
        <mesh filename="$(find mujoco_ros2_ur)/ur_description/meshes/ur5e/collision/meshes/peg.stl"/>
      </geometry>
    </collision>
    <inertial>
      <mass value="0.1" />
      <origin xyz="0.0 0.0 0.0" />
      <inertia ixx = "0.000002" ixy = "0.000000" ixz = "0.000000"
             iyx = "0.000000" iyy = "0.000005" iyz = "0.000000"
             izx = "0.000000" izy = "0.000000" izz = "0.000006" />
    </inertial>
  </link>

  <joint name="peg_joint" type="floating">
    <parent link="base"/>
    <child link="peg"/>
    <axis xyz="0 0 0"/>
    <origin xyz="0.5 0.75 0.02"/>
  </joint> -->
  </xacro:macro>
</robot>